<?xml version="1.0"?>
<robot xmlns:xacro="http://www.ros.org/wiki/xacro" name="front_wheel">

<xacro:include filename="$(find tractor_description)/urdfs/cylinder_inertia.xacro"/>

<xacro:macro name="caster_wheel" params="name translateX translateY radius length">

        
    <xacro:property name="mass" value="0.5" />

    <link name="${name}_caster_wheel">
        <collision>
            <geometry>
                <cylinder radius="${radius}" length="${length}" />
            </geometry>
        </collision>
        <xacro:cylinder_inertia mass="${mass}" radius="${radius}" length="${length}"/>
    </link>

    <joint name="${name}_caster_wheel_joint" type="continuous">
        <origin xyz="${translateX}  ${translateY} -0.23" rpy=" -1.57 0 0" />
        <parent link="base_link" />
        <child link="${name}_caster_wheel" />
        <axis  xyz="0 0 1" />
	<dynamics damping="0" friction="0"/>
    </joint>



    <gazebo reference="${name}_caster_wheel">
        <gravity>true</gravity>
        <mu1>1</mu1>
        <mu2>1</mu2>
        <kd>1</kd>
        <kp>10000000000.0</kp>
        <fdir1>0 0 1</fdir1>
        <selfCollide>false</selfCollide>
    </gazebo>

</xacro:macro>

</robot>
